<mujoco model="3D_Quad">
    <!-- 외부 파일 include (시각 요소, 환경 설정 등) -->
    <include file="./visual.xml"/>
    <include file="./skybox.xml"/>
    <include file="./materials.xml"/>
    <compiler angle="degree" coordinate="local"/>
    <option timestep="0.001" integrator="RK4" gravity="0 0 -9.81"/>
    <default>
        <geom
            friction="1 1 1"
            density="1000"
            margin="0.002"
            condim="3"
            contype="1"
            conaffinity="1"
        />
    </default>
    <worldbody>
        <!-- 카메라 / 라이트 -->
        <camera name="sideview" pos="3 0 1" euler="0 0 90" fovy="45"/>
        <light name="light" pos="0 0 2"/>
        <!-- 바닥 -->
        <geom name="floor" type="plane" size="30 30 0.2" material="grid" pos="0 0 0"/>
        <!-- ────────────────────────────────
             몸통(전방)
           ──────────────────────────────── -->
        <body name="torso_front" pos="0 0 0.375" euler= "0 0 0">
            <!-- 질량/관성: 수정됨 -->
            <inertial pos="0.1 0 0" mass="0.5" diaginertia="0.000225 0.001695 0.001695"/>
            <freejoint/>
            <geom
                type="box"
                size="0.1 0.1 0.01"
                pos="0.1 0 0"
                rgba="0.3 0.3 0.3 1"
            />
            <site name="imu" pos="0. 0 0" size="0.01" rgba="1 0 0 1"/>
            <!--============================================-->
            <!-- 1) 앞다리(왼쪽): Hip (Abduction + Flexion) -->
            <!--============================================-->
            <body name="front_hip_left_abd" pos="0.2 0.15 0" euler="0 90 0">
                <!-- abduction body: 질량/관성 수정됨 -->
                <inertial mass="3.2" diaginertia="0.0025 0.0025 0.0025" pos="0 0 0"/>
                <!-- abduction hinge joint -->
                <joint name="front_hip_left_abd"
                       type="hinge"
                       axis="0 0 1"
                       limited="true"
                       range="-50 50"
                       frictionloss = "0.2"/>
                <!-- 자식 body: flexion hinge -->
                <body name="front_thigh_left" pos="0 0 0">
                    <!-- 질량/관성: 수정됨 -->
                    <inertial pos="0 0 -0.125" mass="0.3" diaginertia="0.0028 0.0028 0.0001567"/>
                    <joint name="front_hip_left" type="hinge" axis="0 -1 0" limited="true" range="0 180" frictionloss = "0.2"/>
                    <geom type="capsule" fromto="0 0 0 0 0 -0.25" size="0.025" rgba="0.1 0.1 0.1 1"/>
                    <!-- 무릎 -->
                    <body name="front_shin_left" pos="0 0 -0.25">
                        <!-- 질량/관성: 수정됨 -->
                        <inertial pos="0 0 -0.125" mass="0.3" diaginertia="0.0026 0.0026 0.0001"/>
                        <joint name="front_knee_left" type="hinge" axis="0 -1 0" limited="true" range="0 180" frictionloss = "0.2"/>
                        <geom type="capsule" fromto="0 0 0 0 0 -0.25" size="0.02" rgba="0.1 0.1 0.1 1"/>
                        <site name="front_foot_left" pos="0 0 -0.25" size="0.01" rgba="0 1 0 1"/>
                    </body>
                </body>
            </body>
            <!--=============================================-->
            <!-- 2) 앞다리(오른쪽): Hip (Abduction + Flexion) -->
            <!--=============================================-->
            <body name="front_hip_right_abd" pos="0.2 -0.15 0" euler="0 90 0">
                <!-- 질량/관성: 수정됨 -->
                <inertial mass="3.2" diaginertia="0.0025 0.0025 0.0025" pos="0 0 0"/>
                <joint name="front_hip_right_abd"
                       type="hinge"
                       axis="0 0 1"
                       limited="true"
                       range="-50 50"
                       frictionloss = "0.2"/>
                <body name="front_thigh_right" pos="0 0 0">
                    <!-- 질량/관성: 수정됨 -->
                    <inertial pos="0 0 -0.125" mass="0.3" diaginertia="0.0028 0.0028 0.0001567"/>
                    <joint name="front_hip_right" type="hinge" axis="0 -1 0" limited="true" range="0 180" frictionloss = "0.2"/>
                    <geom type="capsule" fromto="0 0 0 0 0 -0.25" size="0.025" rgba="0.1 0.1 0.1 1"/>
                    <body name="front_shin_right" pos="0 0 -0.25">
                        <!-- 질량/관성: 수정됨 -->
                        <inertial pos="0 0 -0.125" mass="0.3" diaginertia="0.0026 0.0026 0.0001"/>
                        <joint name="front_knee_right" type="hinge" axis="0 -1 0" limited="true" range="0 180" frictionloss = "0.2"/>
                        <geom type="capsule" fromto="0 0 0 0 0 -0.25" size="0.02" rgba="0.1 0.1 0.1 1"/>
                        <site name="front_foot_right" pos="0 0 -0.25" size="0.01" rgba="0 1 0 1"/>
                    </body>
                </body>
            </body>
            <!-- ───────────────────────────────
                 뒤쪽 몸통 (Spine)
               ─────────────────────────────── -->
            <body name="torso_back" pos="0 0 0">
                <!-- 질량/관성: 수정됨 -->
                <inertial pos="-0.1 0 0" mass="0.9" diaginertia="0.000225 0.001695 0.001695"/>
                <geom type="box" size="0.1 0.1 0.01" pos="-0.1 0 0" rgba="0.2 0.2 0.2 1"/>
                <!-- 허리(waist) hinge -->
                <!-- <joint name="waist" type="hinge" axis="0 -1 0" limited="true" range="-30 30" frictionloss = "0.2"/> -->
                <!--=========================================-->
                <!-- 3) 뒷다리(왼쪽): Hip (Abduction + Flexion) -->
                <!--=========================================-->
                <body name="back_hip_left_abd" pos="-0.2 0.15 0" euler="0 90 0">
                    <!-- 질량/관성: 수정됨 -->
                    <inertial mass="3.2" diaginertia="0.0025 0.0025 0.0025" pos="0 0 0"/>
                    <joint name="back_hip_left_abd"
                           type="hinge"
                           axis="0 0 1"
                           limited="true"
                           range="-50 50"
                           frictionloss = "0.2"/>
                    <body name="back_thigh_left" pos="0 0 0">
                        <!-- 질량/관성: 수정됨 -->
                        <inertial pos="0 0 -0.125" mass="0.3" diaginertia="0.0028 0.0028 0.0001567"/>
                        <joint name="back_hip_left" type="hinge" axis="0 -1 0" limited="true" range="0 180" frictionloss = "0.2"/>
                        <geom type="capsule" fromto="0 0 0 0 0 -0.25" size="0.025" rgba="0.1 0.1 0.1 1"/>
                        <body name="back_shin_left" pos="0 0 -0.25">
                            <!-- 질량/관성: 수정됨 -->
                            <inertial pos="0 0 -0.125" mass="0.3" diaginertia="0.0026 0.0026 0.0001"/>
                            <joint name="back_knee_left" type="hinge" axis="0 -1 0" limited="true" range="0 180" frictionloss = "0.2"/>
                            <geom type="capsule" fromto="0 0 0 0 0 -0.25" size="0.02" rgba="0.1 0.1 0.1 1"/>
                            <site name="back_foot_left" pos="0 0 -0.25" size="0.01" rgba="0 1 0 1"/>
                        </body>
                    </body>
                </body>
                <!--==========================================-->
                <!-- 4) 뒷다리(오른쪽): Hip (Abduction + Flexion) -->
                <!--==========================================-->
                <body name="back_hip_right_abd" pos="-0.2 -0.15 0" euler="0 90 0">
                    <!-- 질량/관성: 수정됨 -->
                    <inertial mass="3.2" diaginertia="0.0025 0.0025 0.0025" pos="0 0 0"/>
                    <joint name="back_hip_right_abd"
                           type="hinge"
                           axis="0 0 1"
                           limited="true"
                           range="-50 50"
                           frictionloss = "0.2"/>
                    <body name="back_thigh_right" pos="0 0 0">
                        <!-- 질량/관성: 수정됨 -->
                        <inertial pos="0 0 -0.125" mass="0.3" diaginertia="0.0028 0.0028 0.0001567"/>
                        <joint name="back_hip_right" type="hinge" axis="0 -1 0" limited="true" range="0 180" frictionloss = "0.2"/>
                        <geom type="capsule" fromto="0 0 0 0 0 -0.25" size="0.025" rgba="0.1 0.1 0.1 1"/>
                        <body name="back_shin_right" pos="0 0 -0.25">
                            <!-- 질량/관성: 수정됨 -->
                            <inertial pos="0 0 -0.125" mass="0.3" diaginertia="0.0026 0.0026 0.0001"/>
                            <joint name="back_knee_right" type="hinge" axis="0 -1 0" limited="true" range="0 180" frictionloss = "0.2"/>
                            <geom type="capsule" fromto="0 0 0 0 0 -0.25" size="0.02" rgba="0.1 0.1 0.1 1"/>
                            <site name="back_foot_right" pos="0 0 -0.25" size="0.01" rgba="0 1 0 1"/>
                        </body>
                    </body>
                </body>
            </body>
        </body>
    </worldbody>
    <actuator>

        <!-- ==== Front ==== -->
        <motor joint="front_hip_left_abd"  ctrlrange="-60 60" gear="1"/>
        <motor joint="front_hip_left"   ctrlrange="-60 60" gear="1"/>
        <motor joint="front_knee_left"  ctrlrange="-60 60" gear="1"/>
        <motor joint="front_hip_right_abd" ctrlrange="-60 60" gear="1"/>
        <motor joint="front_hip_right"  ctrlrange="-60 60" gear="1"/>
        <motor joint="front_knee_right" ctrlrange="-60 60" gear="1"/>


        <!-- 허리(Spine) -->
        <!-- <motor joint="waist" ctrlrange="-60 60" gear="1"/> -->

        <!-- ==== Back ==== -->
        <motor joint="back_hip_left_abd"   ctrlrange="-60 60" gear="1"/>
        <motor joint="back_hip_left"    ctrlrange="-60 60" gear="1"/>
        <motor joint="back_knee_left"   ctrlrange="-60 60" gear="1"/>
        <motor joint="back_hip_right_abd"  ctrlrange="-60 60" gear="1"/>
        <motor joint="back_hip_right"   ctrlrange="-60 60" gear="1"/>
        <motor joint="back_knee_right"  ctrlrange="-60 60" gear="1"/>
    </actuator>
    <sensor>
        <!-- IMU (torso_front) -->
        <accelerometer site="imu" name="imu_accl"/>
        <gyro          site="imu" name="imu_gyro"/>
        <framelinvel  name="trunk_vel"  objtype="site" objname="imu" />
        <framepos  name="trunk_pos"  objtype="site" objname="imu" />
        

        <!-- 발바닥 Force Sensor -->
        <force site="front_foot_left"  name="front_foot_force_left"/>
        <force site="front_foot_right" name="front_foot_force_right"/>
        <force site="back_foot_left"   name="back_foot_force_left"/>
        <force site="back_foot_right"  name="back_foot_force_right"/>


    </sensor>
</mujoco>
